<?xml version="1.0" encoding="utf-8"?>
<!-- This URDF was automatically created by SolidWorks to URDF Exporter! Originally created by Stephen Brawner (brawner@gmail.com) 
     Commit Version: 1.6.0-4-g7f85cfe  Build Version: 1.6.7995.38578
     For more information, please see http://wiki.ros.org/sw_urdf_exporter -->
 <robot name="gcr5">


  <link name="world"/>

  <joint name="fixed" type="fixed">
    <parent link="world"/>
    <child link="base_link"/>
  </joint>



 <link name="base_link">
   <inertial>
   <origin xyz="-5.7382E-18 0.011758 0.021995" rpy="0 0 0" />
   <mass value="40" /> 
   <inertia ixx="1.5625" ixy="0" ixz="0" iyy="2.9167" iyz="0" izz="0" />
   </inertial>
   <visual>
      <origin xyz="0 0 0" rpy="0 0 0" />
      <geometry>
      <mesh filename="package://duco_support/meshes/GCR5_910/base_link.stl" />
      </geometry>
      <material name="">
      <color rgba="0.73333 0.78039 0.83922 1" />
      </material>
   </visual>
   <collision>
      <origin xyz="0 0 0" rpy="0 0 0" />
      <geometry>
      <mesh filename="package://duco_support/meshes/GCR5_910/base_link.stl" />
      </geometry>
   </collision>
  </link>
  <!-- Link 1 -->
  <link name="link_1">
    <inertial>
      <origin xyz="0 0 0" rpy="0 0 0" />
      <mass value="1.657" />
      <inertia ixx="1.0752E-05" ixy="7.523E-09" ixz="1.0743E-08" iyy="1.0133197E-05" iyz="4.49349E-07" izz="7.870754E-05" />
    </inertial>
    <visual>
      <origin xyz="0 0 0" rpy="0 0 0" />
      <geometry>
        <mesh filename="package://duco_support/meshes/GCR5_910/link_1.stl" />
      </geometry>
      <material name="">
       <color rgba="0.79216 0.81961 0.93333 1" />
      </material>
    </visual>
    <collision>
      <origin xyz="0 0 0" rpy="0 0 0" />
      <geometry>
        <mesh filename="package://duco_support/meshes/GCR5_910/link_1.stl" />
      </geometry>
    </collision>
  </link>
  <!-- joint 1 -->
  <joint name="joint_1" type="revolute">
    <origin xyz="0 0 0.122" rpy="0 0 0" />
    <parent link="base_link" />
    <child link="link_1" />
    <axis xyz="0 0 1" />
    <limit lower="-3.1415926" upper="3.1415926" effort="250" velocity="180" />
    <dynamics damping="0.3" friction="0.3" /> 
  </joint>
   <!-- Link 2 -->
  <link name="link_2">
    <inertial>
      <origin xyz="0.21612 -1.8576E-16 0.014189" rpy="0 0 0" />
      <mass value="1.0497" />
      <inertia ixx="0.0069086" ixy="8.2574E-08" ixz="9.7307E-18" iyy="0.022883" iyz="2.8358E-18" izz="0.024046" />
    </inertial>
    <visual>
      <origin xyz="0 0 0" rpy="0 0 0" />
      <geometry>
        <mesh filename="package://duco_support/meshes/GCR5_910/link_2.stl" />
      </geometry>
       <material name="">
       <color rgba="0.79216 0.81961 0.93333 1" />
      </material>
    </visual>
    <collision>
      <origin xyz="0 0 0" rpy="0 0 0" />
      <geometry>
        <mesh filename="package://duco_support/meshes/GCR5_910/link_2.stl" />
      </geometry>
    </collision>
  </link>
   <!-- joint 2 -->
  <joint name="joint_2" type="revolute">
    <origin xyz="0 0.1445 0" rpy="1.5708 -1.5708 3.1416" />
    <parent link="link_1" />
    <child link="link_2" />
    <axis xyz="0 0 1" />
     <limit lower="-1.5708" upper="1.5708"  effort="250" velocity="180" />
    <dynamics damping="0.3" friction="0.3" />
  </joint>
   <!-- Link 3 -->
  <link name="link_3">
    <inertial>
      <origin xyz="0.10177 2.95E-08 -0.11478" rpy="0 0 0" />
      <mass value="0.98857" />
      <inertia ixx="0.0035253" ixy="-2.5122E-08" ixz="0.00038746" iyy="0.010268" iyz="2.8848E-09" izz="0.010609" />
    </inertial>
    <visual>
      <origin xyz="0 0 0" rpy="0 0 0" />
      <geometry>
        <mesh filename="package://duco_support/meshes/GCR5_910/link_3.stl" />
      </geometry>
   <material name="">
       <color rgba="0.79216 0.81961 0.93333 1" />
   </material>
    </visual>
    <collision>
      <origin xyz="0 0 0" rpy="0 0 0" />
      <geometry>
        <mesh filename="package://duco_support/meshes/GCR5_910/link_3.stl" />
      </geometry>
    </collision>
  </link>
   <!-- joint 3 -->
  <joint name="joint_3" type="revolute">
    <origin xyz="0.425 0 0" rpy="0 0 0" />
    <parent link="link_2" />
    <child link="link_3" />
    <axis xyz="0 0 1" />
    <limit lower="-3.1415926" upper="3.1415926" effort="250" velocity="180" />
    <dynamics damping="0.3" friction="0.3" />
  </joint>
   <!-- Link 4 -->
  <link name="link_4">
    <inertial>
      <origin xyz="-7.7387E-07 0.0063161 -0.0061589" rpy="0 0 0" />
      <mass value="0.12228" />
      <inertia ixx="0.00048225" ixy="5.8826E-09" ixz="2.1987E-08" iyy="0.00055656" iyz="5.1696E-05" izz="0.00041144" />
    </inertial>
    <visual>
      <origin xyz="0 0 0" rpy="0 0 0" />
      <geometry>
        <mesh filename="package://duco_support/meshes/GCR5_910/link_4.stl" />
      </geometry>
   <material name="">
       <color rgba="0.79216 0.81961 0.93333 1" />
   </material>
    </visual>
    <collision>
      <origin xyz="0 0 0" rpy="0 0 0" />
      <geometry>
        <mesh filename="package://duco_support/meshes/GCR5_910/link_4.stl" />
      </geometry>
    </collision>
  </link>
   <!-- joint 4 -->
  <joint name="joint_4" type="revolute">
    <origin xyz="0.392 0 0" rpy="0 0 1.5708" />
    <parent link="link_3" />
    <child link="link_4" />
    <axis xyz="0 0 1" />
    <limit lower="-3.1415926" upper="3.1415926" effort="250" velocity="180" />
    <dynamics damping="0.3" friction="0.3" />
  </joint>
   <!-- Link 5 -->
  <link name="link_5">
    <inertial>
      <origin xyz="7.731E-07 -0.008004 0.00087192" rpy="0 0 0" />
      <mass value="0.07906" />
      <inertia ixx="0.00034489" ixy="2.4698E-09" ixz="-2.3229E-08" iyy="0.00042119" iyz="-3.743E-05" izz="0.00034777" />
    </inertial>
    <visual>
      <origin xyz="0 0 0" rpy="0 0 0" />
      <geometry>
        <mesh filename="package://duco_support/meshes/GCR5_910/link_5.stl" />
      </geometry>
   <material name="">
       <color rgba="0.79216 0.81961 0.93333 1" />
   </material>
    </visual>
    <collision>
      <origin xyz="0 0 0" rpy="0 0 0" />
      <geometry>
        <mesh filename="package://duco_support/meshes/GCR5_910/link_5.stl" />
      </geometry>    <dynamics damping="0.7" friction="0.7" />
    </collision>
  </link>
   <!-- Joint 5 -->
  <joint name="joint_5" type="revolute">
    <origin xyz="0 -0.1 0" rpy="1.5708 0 0" />
    <parent link="link_4" />
    <child link="link_5" />
    <axis xyz="0 0 1" />
    <dynamics damping="0.3" friction="0.3" />
    <limit lower="-3.1415926" upper="3.1415926" effort="250" velocity="180" /> 
  </joint>

  <!-- Link 6 -->
  <link name="link_6">
    <inertial>
      <origin xyz="-2.7264E-05 -0.0031969 -0.013722" rpy="0 0 0" />
      <mass value="0.0201" />
      <inertia ixx="0.00010193" ixy="-1.7257E-10" ixz="9.7552E-19"
               iyy="0.00010193" iyz="-7.9276E-20" izz="0.00018851" />
    </inertial>
    <visual>
      <origin xyz="0 0 0" rpy="0 0 0" />
      <geometry>
        <mesh filename="package://duco_support/meshes/GCR5_910/link_6.stl" />
      </geometry>
      <material name="">
        <color rgba="0 0 0 1" />
      </material>
    </visual>
    <collision>
      <origin xyz="0 0 0" rpy="0 0 0" />
      <geometry>
        <mesh filename="package://duco_support/meshes/GCR5_910/link_6.stl" />
      </geometry>
    </collision>
  </link>

  <!-- Joint 6 -->
  <joint name="joint_6" type="revolute">
    <origin xyz="0 0.105 0" rpy="-1.5708 0 0" />
    <parent link="link_5" />
    <child link="link_6" />
    <axis xyz="0 0 1" />
    <dynamics damping="0.3" friction="0.3" />
      <limit lower="-3.1415926" upper="3.1415926" effort="250" velocity="180" /> 
  </joint>

  <!--ftlink-->
    <link name="ft_sensor">
     <visual>
         <geometry>
             <cylinder radius="0.0375" length="0.01"/>
         </geometry>
         <origin xyz="0.0 0.0 0.0" rpy="0.0 0.0 0.0"/>
     </visual>
     <collision>
         <geometry>
             <cylinder radius="0.0375" length="0.01"/>
         </geometry>
         <origin xyz="0.0 0.0 0.0" rpy="1.5708 0.0 0.0"/>
     </collision>
     <inertial>
         <mass value="0.01"/>
         <inertia ixx="7.1441E-05" ixy="1.6499E-08" ixz="-4.9269E-09"
                  iyy="7.146E-05" iyz="-8.5336E-09" izz="0.00013366"/>
     </inertial>
     </link>
  
  <!-- Joint ft -->
     <joint name="ft_sensor_joint" type="fixed"> 
     <origin xyz="0.0 0.0 0.0" rpy="0.0 0.0 0.0"/>
     <parent link="link_6"/>
     <child link="ft_sensor"/>
     <axis xyz="0.0 0.0 0.0"/>
     <limit lower="0.0" upper="0.0" effort="0.0" velocity="0.0"/>
   </joint>
  <transmission name="trans_joint1">
    <type>transmission_interface/SimpleTransmission</type>
    <joint name="joint_1">
      <hardwareInterface>hardware_interface/PositionJointInterface</hardwareInterface>
    </joint>
    <actuator name="motor1">
      <hardwareInterface>hardware_interface/PositionJointInterface</hardwareInterface>
      <mechanicalReduction>1</mechanicalReduction>
    </actuator>
  </transmission>

  <transmission name="trans_joint2">
    <type>transmission_interface/SimpleTransmission</type>
    <joint name="joint_2">
      <hardwareInterface>hardware_interface/PositionJointInterface</hardwareInterface>
    </joint>
    <actuator name="motor2">
      <hardwareInterface>hardware_interface/PositionJointInterface</hardwareInterface>
      <mechanicalReduction>1</mechanicalReduction>
    </actuator>
  </transmission>

  <transmission name="trans_joint3">
    <type>transmission_interface/SimpleTransmission</type>
    <joint name="joint_3">
      <hardwareInterface>hardware_interface/PositionJointInterface</hardwareInterface>
    </joint>
    <actuator name="motor3">
      <hardwareInterface>hardware_interface/PositionJointInterface</hardwareInterface>
      <mechanicalReduction>1</mechanicalReduction>
    </actuator>
  </transmission>

  <transmission name="trans_joint4">
    <type>transmission_interface/SimpleTransmission</type>
    <joint name="joint_4">
      <hardwareInterface>hardware_interface/PositionJointInterface</hardwareInterface>
    </joint>
    <actuator name="motor4">
      <hardwareInterface>hardware_interface/PositionJointInterface</hardwareInterface>
      <mechanicalReduction>1</mechanicalReduction>
    </actuator>
  </transmission>

  <transmission name="trans_joint5">
    <type>transmission_interface/SimpleTransmission</type>
    <joint name="joint_5">
      <hardwareInterface>hardware_interface/PositionJointInterface</hardwareInterface>
    </joint>
    <actuator name="motor5">
      <hardwareInterface>hardware_interface/PositionJointInterface</hardwareInterface>
      <mechanicalReduction>1</mechanicalReduction>
    </actuator>
  </transmission>

  <transmission name="trans_joint6">
    <type>transmission_interface/SimpleTransmission</type>
    <joint name="joint_6">
      <hardwareInterface>hardware_interface/PositionJointInterface</hardwareInterface>
    </joint>
    <actuator name="motor6">
      <hardwareInterface>hardware_interface/PositionJointInterface</hardwareInterface>
      <mechanicalReduction>1</mechanicalReduction>
    </actuator>
  </transmission>

  <!-- ROS2 Control configuration -->
  <ros2_control name="MyRobotHardware" type="system">
    <hardware>
      <plugin>gazebo_ros2_control/GazeboSystem</plugin>
    </hardware>
    <joint name="joint_1">
      <command_interface name="position" />
      <state_interface name="position" />
      <state_interface name="velocity" />
    </joint>
    <joint name="joint_2">
      <command_interface name="position" />
      <state_interface name="position" />
      <state_interface name="velocity" />
    </joint>
    <joint name="joint_3">
      <command_interface name="position" />
      <state_interface name="position" />
      <state_interface name="velocity" />
    </joint>
    <joint name="joint_4">
      <command_interface name="position" />
      <state_interface name="position" />
      <state_interface name="velocity" />
    </joint>
    <joint name="joint_5">
      <command_interface name="position" />
      <state_interface name="position" />
      <state_interface name="velocity" />
    </joint>
     <joint name="joint_6">
      <command_interface name="position" />
      <state_interface name="position" />
      <state_interface name="velocity" />
    </joint>
  </ros2_control>
  <gazebo reference="base_link">
    <material>Gazebo/White</material>
    <static>true</static>
  </gazebo>

  <gazebo reference="link_1">
    <material>Gazebo/Blue</material>
  </gazebo>

  <gazebo reference="link_2">
    <material>Gazebo/Blue</material>
  </gazebo>

  <gazebo reference="link_3">
    <material>Gazebo/Blue</material>
  </gazebo>

  <gazebo reference="link_4">
    <material>Gazebo/Blue</material>
  </gazebo>

  <gazebo reference="link_5">
    <material>Gazebo/Blue</material>
  </gazebo>
  <gazebo reference="link_6">
    <material>Gazebo/Blue</material>
  </gazebo>

 
     <gazebo reference="ft_sensor_joint">
     <provideFeedback>true</provideFeedback>
     <disableFixedJointLumping>true</disableFixedJointLumping>
     </gazebo>
     
        <gazebo reference="ft_sensor_joint">
    <gravity>true</gravity>
    <sensor name="ft_sensor" type="force_torque">
      <always_on>true</always_on>
      <visualize>true</visualize>
    </sensor>
      </gazebo>

  <gazebo>
    <plugin name="gazebo_ros_control" filename="libgazebo_ros_control.so">
      <robot_namespace>/</robot_namespace>
      <robot_param>robot_description</robot_param>
      <robot_param_node>robot_state_publisher</robot_param_node>
      <parameters>/home/shenyi/duco_ws/src/duco_gcr5_moveit_config/config/ros_controllers.yaml</parameters>
    </plugin>
  </gazebo>
</robot>
